Workbook

Sheet Financial summary
A1: FINANCIAL SUMMARY
A2: Rating / target — see Valuation tab
A3: Recommendation | B3: =Valuation!B23
A4: Fair value / share (₱) | B4: =Valuation!B20
A5: Upside | B5: =Valuation!B22
A7: ₱000 / FY | B7: 2024E | C7: 2025E | D7: 2026E | E7: 2027E
A8: Revenue | B8: =Model!B4 | C8: =Model!C4 | D8: =Model!D4 | E8: =Model!E4
A9: EBIT | B9: =Model!B5 | C9: =Model!C5 | D9: =Model!D5 | E9: =Model!E5
A10: NOPAT | B10: =Model!B6 | C10: =Model!C6 | D10: =Model!D6 | E10: =Model!E6
A11: Free cash flow | B11: =Model!B11 | C11: =Model!C11 | D11: =Model!D11 | E11: =Model!E11
A12: Net income (parent) | B12: =Model!B13 | C12: =Model!C13 | D12: =Model!D13 | E12: =Model!E13
A13: EPS (₱) | B13: =Model!B14 | C13: =Model!C14 | D13: =Model!D14 | E13: =Model!E14

Sheet Assumptions
A1: ASSUMPTIONS — edit blue cells; the model recomputes
A2: Risk-free rate (PH 10Y) | B2: 0.06
A3: Mature-market ERP | B3: 0.046
A4: Beta (observed) | B4: 0.46
A5: Country risk premium | B5: 0.03
A6: Cost of equity (CAPM+CRP) | B6: =$B$2+$B$4*$B$3+$B$5
A7: Pre-tax cost of debt | B7: 0.057
A8: Tax rate | B8: 0.25
A9: After-tax cost of debt | B9: =$B$7*(1-$B$8)
A10: Equity weight (target) | B10: 0.6
A11: Debt weight (target) | B11: 0.4
A12: WACC | B12: =$B$10*$B$6+$B$11*$B$9
A13: Terminal growth | B13: 0.025
A15: EBIT margin | B15: 0.54687904
A16: D&A % of revenue | B16: 0.13550503
A17: CapEx % revenue (base) | B17: 0.64010407
A18: CapEx % revenue (terminal) | B18: 0.3
A19: Δ NWC % of Δrevenue | B19: 0.01
A21: Base revenue FY2024E (₱000) | B21: 36729421
A22: Base parent net income FY2024E (₱000) | B22: 13470128
A23: Net margin (parent) | B23: =$B$22/$B$21
A25: Revenue growth 2025 | B25: 0.1
A26: Revenue growth 2026 | B26: 0.08
A27: Revenue growth 2027 | B27: 0.07
A28: Revenue growth 2028 | B28: 0.06
A29: Revenue growth 2029 | B29: 0.05
A31: Net debt (₱000) | B31: 94514464
A32: Non-controlling interests (₱000) | B32: 1973326
A33: Preferred (book, ₱000) | B33: 400000
A34: Common shares outstanding | B34: 2597094010
A35: Current price (₱) | B35: 22.36

Sheet Model
A1: THREE-STATEMENT MODEL (₱ thousands)
A2: ₱000 / FY | B2: 2024E | C2: 2025E | D2: 2026E | E2: 2027E | F2: 2028F | G2: 2029F
A4: Revenue | B4: =Assumptions!$B$21 | C4: =B4*(1+Assumptions!$B$25) | D4: =C4*(1+Assumptions!$B$26) | E4: =D4*(1+Assumptions!$B$27) | F4: =E4*(1+Assumptions!$B$28) | G4: =F4*(1+Assumptions!$B$29)
A5: EBIT | B5: =B4*Assumptions!$B$15 | C5: =C4*Assumptions!$B$15 | D5: =D4*Assumptions!$B$15 | E5: =E4*Assumptions!$B$15 | F5: =F4*Assumptions!$B$15 | G5: =G4*Assumptions!$B$15
A6: NOPAT | B6: =B5*(1-Assumptions!$B$8) | C6: =C5*(1-Assumptions!$B$8) | D6: =D5*(1-Assumptions!$B$8) | E6: =E5*(1-Assumptions!$B$8) | F6: =F5*(1-Assumptions!$B$8) | G6: =G5*(1-Assumptions!$B$8)
A7: D&A | B7: =B4*Assumptions!$B$16 | C7: =C4*Assumptions!$B$16 | D7: =D4*Assumptions!$B$16 | E7: =E4*Assumptions!$B$16 | F7: =F4*Assumptions!$B$16 | G7: =G4*Assumptions!$B$16
A8: CapEx % revenue | B8: =Assumptions!$B$17 | C8: =Assumptions!$B$17+(Assumptions!$B$18-Assumptions!$B$17)*0.2 | D8: =Assumptions!$B$17+(Assumptions!$B$18-Assumptions!$B$17)*0.4 | E8: =Assumptions!$B$17+(Assumptions!$B$18-Assumptions!$B$17)*0.6 | F8: =Assumptions!$B$17+(Assumptions!$B$18-Assumptions!$B$17)*0.8 | G8: =Assumptions!$B$17+(Assumptions!$B$18-Assumptions!$B$17)*1.0
A9: CapEx | B9: =B4*B8 | C9: =C4*C8 | D9: =D4*D8 | E9: =E4*E8 | F9: =F4*F8 | G9: =G4*G8
A10: Δ NWC | B10: =0 | C10: =(C4-B4)*Assumptions!$B$19 | D10: =(D4-C4)*Assumptions!$B$19 | E10: =(E4-D4)*Assumptions!$B$19 | F10: =(F4-E4)*Assumptions!$B$19 | G10: =(G4-F4)*Assumptions!$B$19
A11: Free cash flow (FCFF) | B11: =B6+B7-B9-B10 | C11: =C6+C7-C9-C10 | D11: =D6+D7-D9-D10 | E11: =E6+E7-E9-E10 | F11: =F6+F7-F9-F10 | G11: =G6+G7-G9-G10
A13: Net income (parent) | B13: =Assumptions!$B$22 | C13: =C4*Assumptions!$B$23 | D13: =D4*Assumptions!$B$23 | E13: =E4*Assumptions!$B$23 | F13: =F4*Assumptions!$B$23 | G13: =G4*Assumptions!$B$23
A14: EPS (₱) | B14: =B13*1000/Assumptions!$B$34 | C14: =C13*1000/Assumptions!$B$34 | D14: =D13*1000/Assumptions!$B$34 | E14: =E13*1000/Assumptions!$B$34 | F14: =F13*1000/Assumptions!$B$34 | G14: =G13*1000/Assumptions!$B$34
A15: EPS growth | C15: =C14/B14-1 | D15: =D14/C14-1 | E15: =E14/D14-1 | F15: =F14/E14-1 | G15: =G14/F14-1

Sheet Valuation
A1: DCF VALUATION
A2: WACC | B2: =Assumptions!$B$12
A3: Terminal growth | B3: =Assumptions!$B$13
A5: FY | C5: 2025E | D5: 2026E | E5: 2027E | F5: 2028F | G5: 2029F
A6: Free cash flow | C6: =Model!C11 | D6: =Model!D11 | E6: =Model!E11 | F6: =Model!F11 | G6: =Model!G11
A7: Discount factor | C7: =1/(1+$B$2)^1 | D7: =1/(1+$B$2)^2 | E7: =1/(1+$B$2)^3 | F7: =1/(1+$B$2)^4 | G7: =1/(1+$B$2)^5
A8: PV of FCF | C8: =C6*C7 | D8: =D6*D7 | E8: =E6*E7 | F8: =F6*F7 | G8: =G6*G7
A10: Σ PV of explicit FCF | B10: =SUM(C8:G8)
A11: Terminal-year FCF | B11: =G6
A12: Terminal value (Gordon) | B12: =B11*(1+B3)/(B2-B3)
A13: PV of terminal value | B13: =B12/(1+B2)^5
A14: Enterprise value | B14: =B10+B13
A15: Less: net debt | B15: =-Assumptions!$B$31
A16: Less: NCI | B16: =-Assumptions!$B$32
A17: Less: preferred | B17: =-Assumptions!$B$33
A18: Common equity value | B18: =B14+B15+B16+B17
A19: Common shares | B19: =Assumptions!$B$34
A20: FAIR VALUE / SHARE (₱) | B20: =B18*1000/B19
A21: Current price (₱) | B21: =Assumptions!$B$35
A22: Upside / (downside) | B22: =B20/B21-1
A23: Recommendation | B23: =IF(B22>0.1,"BUY",IF(B22>=0,"HOLD","UNDERPERFORM"))
A26: SENSITIVITY — fair value/share (₱)
A27: WACC ↓ / g → | C27: 0.015 | D27: 0.02 | E27: 0.025 | F27: 0.03 | G27: 0.035
A28: 0.0738 | C28: 29.77 | D28: 35.6 | E28: 42.63 | F28: 51.26 | G28: 62.12
A29: 0.0788 | C29: 23.71 | D29: 28.54 | E29: 34.27 | F29: 41.16 | G29: 49.64
A30: 0.0838 | C30: 18.55 | D30: 22.6 | E30: 27.34 | F30: 32.96 | G30: 39.73
A31: 0.0888 | C31: 14.1 | D31: 17.54 | E31: 21.52 | F31: 26.17 | G31: 31.69
A32: 0.0938 | C32: 10.23 | D32: 13.18 | E32: 16.55 | F32: 20.45 | G32: 25.02

Sheet Interim
A1: INTERIM RESULTS — income statement (₱000, from filing)
B2: Q3 2024 | C2: Q3 2023 | D2: 9M 2024 | E2: 9M 2023
A3: Water and used water revenues | B3: 8683338 | C3: 7331123 | D3: 26045906 | E3: 21311373
A4: Other operating revenues | B4: 465918 | C4: 346921 | D4: 1363177 | E4: 1619191
A5: FINANCE INCOME FROM CONTRACT ASSETS | B5: 43613 | C5: 74921 | D5: 137983 | E5: 213636
B6: 9192869 | C6: 7752965 | D6: 27547066 | E6: 23144200
A7: Depreciation and amortization | B7: 1161973 | C7: 958371 | D7: 3274208 | E7: 2703583
A8: Power, light and water | B8: 606697 | C8: 583914 | D8: 1819059 | E8: 1791680
A9: Salaries, wages and employee benefits | B9: 348337 | C9: 386785 | D9: 1026250 | E9: 960288
A10: Water treatment chemicals | B10: 133918 | C10: 102356 | D10: 302219 | E10: 253980
A11: Regulatory costs | B11: 118692 | C11: 96825 | D11: 360164 | E11: 289858
A12: Contractual services | B12: 116346 | C12: 130462 | D12: 311571 | E12: 519472
A13: Repairs and maintenance | B13: 100236 | C13: 110011 | D13: 390275 | E13: 339242
A14: Wastewater costs | B14: 55361 | C14: 43313 | D14: 163281 | E14: 162036
A15: Water tankering and bulk water | B15: -46609 | C15: 62913 | D15: 150729 | E15: 183378
A16: Collection fees | B16: 41425 | C16: 41796 | D16: 121415 | E16: 119022
A17: Amortization of water service connections | B17: 37265 | C17: 48999 | D17: 132065 | E17: 135767
A18: Other expenses | B18: 106910 | C18: 68374 | D18: 398691 | E18: 199237
B19: 2780551 | C19: 2634119 | D19: 8449927 | E19: 7657543
A20: GROSS PROFIT | B20: 6412318 | C20: 5118846 | D20: 19097139 | E20: 15486657
A21: OPERATING EXPENSES | B21: 1430382 | C21: 1267584 | D21: 4032226 | E21: 3933620
A22: INCOME BEFORE OTHER INCOME (EXPENSES) | B22: 4981936 | C22: 3851262 | D22: 15064913 | E22: 11553037
A23: Revenue from rehabilitation works | B23: 6567710 | C23: 4572085 | D23: 16237206 | E23: 11493301
A24: Cost of rehabilitation works | B24: -6567710 | C24: -4572085 | D24: -16237206 | E24: -11493301
A25: Foreign exchange gains (losses) – net | B25: 1478636 | C25: -645894 | D25: -590464 | E25: -401449
A26: Foreign currency differentials | B26: -1452565 | C26: 640744 | D26: 870537 | E26: 397255
A27: Interest expense | B27: -902882 | C27: -913565 | D27: -2730796 | E27: -2825693
A28: Interest income | B28: 104031 | C28: 79757 | D28: 302165 | E28: 235436
A29: Equity share in net income of associates | B29: 79001 | C29: 113715 | D29: 293909 | E29: 408948
A30: Losses on disposal of property and equipment – net | B30: -253 | C30: -1541 | D30: -83 | E30: -10882
A31: Other income (losses) - net | B31: 68164 | C31: -1799 | D31: 497563 | E31: 346197
B32: -625868 | C32: -728583 | D32: -1357169 | E32: -1850188
A33: INCOME BEFORE INCOME TAX FROM CONTINUING OPERATIONS | B33: 4356068 | C33: 3122679 | D33: 13707744 | E33: 9702849
A34: PROVISION FOR INCOME TAX - NET | B34: 1026274 | C34: 817676 | D34: 3217354 | E34: 2178219
A35: NET INCOME FROM CONTINUING OPERATIONS | B35: 3329794 | C35: 2305003 | D35: 10490390 | E35: 7524630
A36: NET LOSS FROM DISCONTINUED OPERATIONS | B36: -856 | C36: -9 | D36: -1319 | E36: -724
A37: NET INCOME | B37: 3328938 | C37: 2304994 | D37: 10489071 | E37: 7523906
A38: Cumulative translation adjustment | B38: 517375 | C38: 225749 | D38: -99026 | E38: 348164
A39: Gain (loss) on net investment hedge | B39: 254032 | C39: -135153 | D39: -64831 | E39: -80693
A40: Gain on cash flow hedge | C40: 666092 | E40: 507977
...

Sheet Segments
A1: SEGMENTS — Note 15, 9M 2024 (₱000, from filing)
B2: Manila Conc. | C2: Domestic | D2: Foreign | E2: Consol. adj. | F2: Consolidated
A3: Sales to external customers | B3: 21774720 | C3: 7470249 | D3: 3384 | E3: -1839270 | F3: 27409083
A4: Finance income from contract assets | C4: 137983 | F4: 137983
A5: Costs and expenses (excluding depreciation and amortization) | B5: 6091672 | C5: 4245541 | D5: 56636 | E5: -1644463 | F5: 8749386
A6: Depreciation and amortization | B6: 3038254 | C6: 720631 | D6: 958 | E6: -27077 | F6: 3732766
A7: Equity share in net income of associates | D7: 293909 | F7: 293909
A8: Other income (expenses) - net | B8: -533970 | C8: -471283 | D8: 3569 | E8: -649395 | F8: -1651079
A9: Income (loss) before income tax | B9: 12110824 | C9: 2170777 | D9: 243268 | E9: -817125 | F9: 13707744
A10: Provision for income tax | B10: 2785490 | C10: 415151 | D10: 506 | E10: 16207 | F10: 3217354
A11: Net income (loss) from continuing operations | B11: 9325334 | C11: 1755626 | D11: 242762 | E11: -833332 | F11: 10490390
A12: Net loss from discontinued operations | C12: -1319 | F12: -1319
A13: Net income (loss) | B13: 9325334 | C13: 1754307 | D13: 242762 | E13: -833332 | F13: 10489071
A14: Segment assets excluding investment in associates | B14: 186715025 | C14: 45888061 | D14: 14852941 | E14: -35392208 | F14: 212063819
A15: Investment in associates | D15: 10761891 | E15: 771784 | F15: 11533675
A16: Segment liabilities | B16: 113004376 | C16: 29384270 | D16: 12935986 | E16: -9320502 | F16: 146004130

Sheet Charts
A1: CHARTS
